Workbook

Sheet Instructions
A1: Knotica Solutions Inc: Billing Register (Invoices, Payments and Credit Notes)
A3: Purpose | B3: Operational register for invoice (INV-YYYY-###), payment acknowledgement (RCT-YYYY-###) and credit note (CN-YYYY-###) IDs, balances, ageing and client billing profiles. It is NOT the accounting ledger: reconcile it to your accounting system and bank every month.
A4: Sheets | B4: Dashboard (next IDs, integrity checks, receivables, ageing) | Invoices | Payments | Credit Notes | Clients (billing profile per client) | Lists (dropdown options).
A6: HOW TO ADD AN INVOICE
A7: 1 | B7: Add the client to Clients first (code, name, payment terms, currency, PO rule).
A8: 2 | B8: Open Dashboard and copy the 'Next Invoice ID'. In Invoices, go to the first empty row and paste it as a value (Paste Special > Values).
A9: 3 | B9: Fill the blue cells: client code, quotation / change request, billing type, issue date, currency, subtotal, tax rate. Terms, due date, tax amount, total and balance calculate. Terms come from the client's profile; overwrite the yellow cell only for a one-off.
A10: 4 | B10: Keep Workflow Status at Draft while preparing. Set it to Issued when the invoice is sent to the client.
A11: 5 | B11: File the document in billing/invoices/<year>/ with the same ID, and copy the PDF to the client's 07-billing folder.
A12: HOW TO RECORD A PAYMENT
A13: 1 | B13: Copy the 'Next Payment ID' from the Dashboard and paste it as a value in the first empty row of Payments.
A14: 2 | B14: Choose the Invoice ID from the dropdown. Enter the amount received, any tax withheld by the client, and any bank charges or short payment you absorb. 'Amount Applied' adds the three.
A15: 3 | B15: Enter the bank or remittance REFERENCE only. Never enter bank account or card numbers.
A16: 4 | B16: A part payment leaves the balance open. When the balance reaches zero the Payment Status becomes Paid.
A17: HOW TO ISSUE A CREDIT NOTE
A18: 1 | B18: Take the 'Next Credit Note ID', pick the related invoice, enter the credit amount (including tax), reason and status.
A19: 2 | B19: A credit note reduces the invoice balance only when its Status is Issued. Management approves it first (Approved By).
A20: HOW STATUS AND BALANCES WORK
A21: Workflow Status (you set) | B21: Draft > Issued > Disputed (if the client disputes) > Void (cancelled number).
A22: Payment Status (calculated) | B22: Outstanding, Part-paid, Overdue, Part-paid overdue, Paid, Overpaid. Disputed and Void override the calculation.
A23: Balance Due | B23: Invoice total - issued credit notes - payments applied. Payments applied = amount received + tax withheld by client + bank charges absorbed.
A24: Receivables | B24: Only Issued and Disputed invoices count as receivables. Draft and Void never do. Overdue means the due date has passed and a balance remains.
A26: RULES
A27: Never delete a row | B27: Set Workflow Status to Void instead. The 'Next ID' formulas count existing IDs for the year, so deleting rows can create duplicates.
A28: IDs are permanent | B28: Do not edit an ID after it is issued. Duplicates are highlighted red and counted on the Dashboard.
A29: Issued invoices are final | B29: Correct an issued invoice with a credit note (and a new invoice if needed). Do not change its amounts.
A30: One editor at a time | B30: This is a binary file in Git: two people editing at once cause a conflict. Assign one register owner, or keep the live file in SharePoint / Google Drive and put a copy in the repo.
A31: One currency per payment | B31: A payment must be in the same currency as its invoice. Dashboard totals add amounts without currency conversion.
A32: No sensitive data | B32: Never record bank account numbers, card numbers or passwords. Contacts by role where possible.
A33: Capacity | B33: 500 invoices, 500 payments, 200 credit notes, 100 clients. Extend the formulas down (or start a new yearly file) before you reach the end.
A35: COLOUR LEGEND
A36: Blue text | B36: Cell you type into.
A37: Black text on grey | B37: Formula. Do not overwrite.
A38: Yellow fill | B38: Key assumption or value you may override (reporting year, default payment terms, invoice terms).
A40: ASSUMPTIONS
A41: Default terms (30 days) | B41: Dashboard cell B6. An assumption for you to confirm. Management sets the real standard in handbook/policies/billing-policy.md.
A42: Example rows | B42: Row 6 on Invoices, Payments, Credit Notes and Clients is an example (Northwind Bank). The 10% tax rate is an illustration only. Overwrite the examples with real entries.

Sheet Dashboard
A1: Knotica Solutions Inc: Billing Dashboard
A2: Everything on this sheet is calculated from the Invoices, Payments, Credit Notes and Clients sheets. Single currency assumed (no conversion).
A4: Settings and next IDs
A5: Reporting year (overwrite with a number to change) | B5: =YEAR(TODAY()) -> 2026
A6: Default payment terms in days (used when a client has none) | B6: 30 | C6: Assumption: edit to your standard terms
A7: Next Invoice ID (copy into the Invoices sheet) | B7: ="INV-"&$B$5&"-"&TEXT(COUNTIF(Invoices!$A$6:$A$505,"INV-"&$B$5&"-*")+1,"000") -> INV-2026-002
A8: Next Payment ID (copy into the Payments sheet) | B8: ="RCT-"&$B$5&"-"&TEXT(COUNTIF(Payments!$A$6:$A$505,"RCT-"&$B$5&"-*")+1,"000") -> RCT-2026-002
A9: Next Credit Note ID (copy into the Credit Notes sheet) | B9: ="CN-"&$B$5&"-"&TEXT(COUNTIF('Credit Notes'!$A$6:$A$205,"CN-"&$B$5&"-*")+1,"000") -> CN-2026-002
A11: Integrity checks (all should be 0)
A12: Duplicate invoice IDs | B12: =SUMPRODUCT((Invoices!$A$6:$A$505<>"")*(COUNTIF(Invoices!$A$6:$A$505,Invoices!$A$6:$A$505)>1)) -> 0 | C12: =IF($B12=0,"OK","CHECK") -> OK
A13: Duplicate payment IDs | B13: =SUMPRODUCT((Payments!$A$6:$A$505<>"")*(COUNTIF(Payments!$A$6:$A$505,Payments!$A$6:$A$505)>1)) -> 0 | C13: =IF($B13=0,"OK","CHECK") -> OK
A14: Duplicate credit note IDs | B14: =SUMPRODUCT(('Credit Notes'!$A$6:$A$205<>"")*(COUNTIF('Credit Notes'!$A$6:$A$205,'Credit Notes'!$A$6:$A$205)>1)) -> 0 | C14: =IF($B14=0,"OK","CHECK") -> OK
A15: Invoices with an unknown client code | B15: =SUMPRODUCT((Invoices!$B$6:$B$505<>"")*(COUNTIF(Clients!$A$6:$A$105,Invoices!$B$6:$B$505)=0)) -> 0 | C15: =IF($B15=0,"OK","CHECK") -> OK
A16: Payments pointing to a missing invoice | B16: =SUMPRODUCT((Payments!$C$6:$C$505<>"")*(COUNTIF(Invoices!$A$6:$A$505,Payments!$C$6:$C$505)=0)) -> 0 | C16: =IF($B16=0,"OK","CHECK") -> OK
A17: Credit notes pointing to a missing invoice | B17: =SUMPRODUCT(('Credit Notes'!$B$6:$B$205<>"")*(COUNTIF(Invoices!$A$6:$A$505,'Credit Notes'!$B$6:$B$205)=0)) -> 0 | C17: =IF($B17=0,"OK","CHECK") -> OK
A18: Payments recorded against Draft or Void invoices | B18: =SUMPRODUCT((Payments!$C$6:$C$505<>"")*((COUNTIFS(Invoices!$A$6:$A$505,Payments!$C$6:$C$505,Invoices!$T$6:$T$505,"Draft")+COUNTIFS(Invoices!$A$6:$A$505,Payments!$C$6:$C$505,Invoices!$T$6:$T$505,"Void"))>0)) -> 0 | C18: =IF($B18=0,"OK","CHECK") -> OK
A19: Overpaid invoices (balance below zero) | B19: =COUNTIF(Invoices!$U$6:$U$505,"Overpaid") -> 0 | C19: =IF($B19=0,"OK","CHECK") -> OK
A20: Issued invoices missing issue date or subtotal | B20: =SUMPRODUCT(((Invoices!$T$6:$T$505="Issued")+(Invoices!$T$6:$T$505="Disputed"))*(((Invoices!$I$6:$I$505="")+(Invoices!$M$6:$M$505=""))>0)) -> 0 | C20: =IF($B20=0,"OK","CHECK") -> OK
A22: Receivables (all years; Issued and Disputed invoices only)
A23: Open invoices (balance above zero) | B23: =COUNTIFS(Invoices!$T$6:$T$505,"Issued",Invoices!$S$6:$S$505,">0.005")+COUNTIFS(Invoices!$T$6:$T$505,"Disputed",Invoices!$S$6:$S$505,">0.005") -> 1
A24: Outstanding receivables (positive balances) | B24: =SUMIFS(Invoices!$S$6:$S$505,Invoices!$T$6:$T$505,"Issued",Invoices!$S$6:$S$505,">0.005")+SUMIFS(Invoices!$S$6:$S$505,Invoices!$T$6:$T$505,"Disputed",Invoices!$S$6:$S$505,">0.005") -> 6400
A25: Overdue invoices | B25: =COUNTIF(Invoices!$V$6:$V$505,">0") -> 0
A26: Overdue amount | B26: =SUMIFS(Invoices!$S$6:$S$505,Invoices!$V$6:$V$505,">0") -> 0
A27: Disputed amount outstanding | B27: =SUMIFS(Invoices!$S$6:$S$505,Invoices!$T$6:$T$505,"Disputed") -> 0
A28: Overdue share of receivables | B28: =IF($B$24<=0,"n/a",$B$26/$B$24) -> 0
A29: Overpayments held as client credit | B29: =-(SUMIFS(Invoices!$S$6:$S$505,Invoices!$T$6:$T$505,"Issued",Invoices!$S$6:$S$505,"<-0.005")+SUMIFS(Invoices!$S$6:$S$505,Invoices!$T$6:$T$505,"Disputed",Invoices!$S$6:$S$505,"<-0.005")) -> 0 | C29: Apply to next invoice or refund
A30: Key figures for the reporting year
A31: Invoices issued | B31: =COUNTIFS(Invoices!$A$6:$A$505,"INV-"&$B$5&"-*",Invoices!$T$6:$T$505,"Issued")+COUNTIFS(Invoices!$A$6:$A$505,"INV-"&$B$5&"-*",Invoices!$T$6:$T$505,"Disputed") -> 1
A32: Total invoiced (incl. tax) | B32: =SUMIFS(Invoices!$P$6:$P$505,Invoices!$A$6:$A$505,"INV-"&$B$5&"-*",Invoices!$T$6:$T$505,"Issued")+SUMIFS(Invoices!$P$6:$P$505,Invoices!$A$6:$A$505,"INV-"&$B$5&"-*",Invoices!$T$6:$T$505,"Disputed") -> 26400
A33: Cash received in the year | B33: =SUMPRODUCT((Payments!$B$6:$B$505<>"")*(YEAR(Payments!$B$6:$B$505)=$B$5)*Payments!$F$6:$F$505) -> 20000 | C33: By date received
A34: Tax withheld by clients recorded in the year | B34: =SUMPRODUCT((Payments!$B$6:$B$505<>"")*(YEAR(Payments!$B$6:$B$505)=$B$5)*Payments!$G$6:$G$505) -> 0
A35: Credit notes issued in the year | B35: =SUMIFS('Credit Notes'!$F$6:$F$205,'Credit Notes'!$A$6:$A$205,"CN-"&$B$5&"-*",'Credit Notes'!$H$6:$H$205,"Issued") -> 0
A36: Collected on this year's invoices | B36: =SUMIFS(Invoices!$R$6:$R$505,Invoices!$A$6:$A$505,"INV-"&$B$5&"-*",Invoices!$T$6:$T$505,"Issued")+SUMIFS(Invoices!$R$6:$R$505,Invoices!$A$6:$A$505,"INV-"&$B$5&"-*",Invoices!$T$6:$T$505,"Disputed") -> 20000 | C36: Payments applied, incl. withheld tax
A37: Collection rate on this year's invoices | B37: =IF($B$32=0,"n/a",$B$36/$B$32) -> 0.75757576
A39: Receivables ageing
A40: Ageing bucket | B40: Invoices | C40: Balance due
A41: Not yet due | B41: =COUNTIF(Invoices!$W$6:$W$505,$A41) -> 1 | C41: =SUMIFS(Invoices!$S$6:$S$505,Invoices!$W$6:$W$505,$A41) -> 6400
A42: 1 to 30 days | B42: =COUNTIF(Invoices!$W$6:$W$505,$A42) -> 0 | C42: =SUMIFS(Invoices!$S$6:$S$505,Invoices!$W$6:$W$505,$A42) -> 0
A43: 31 to 60 days | B43: =COUNTIF(Invoices!$W$6:$W$505,$A43) -> 0 | C43: =SUMIFS(Invoices!$S$6:$S$505,Invoices!$W$6:$W$505,$A43) -> 0
A44: 61 to 90 days | B44: =COUNTIF(Invoices!$W$6:$W$505,$A44) -> 0 | C44: =SUMIFS(Invoices!$S$6:$S$505,Invoices!$W$6:$W$505,$A44) -> 0
...

Sheet Invoices
A1: Knotica Solutions Inc: Invoice Register
A2: One row per invoice. IDs follow INV-YYYY-###. Never delete rows: set Workflow Status to Void.
A3: Blue = type here | Black on grey = formula (do not edit) | Yellow = may be overridden
A5: Invoice ID | B5: Client Code | C5: Client Name | D5: Project / Contract Ref | E5: Related Quotation / CR | F5: Client PO / Ref | G5: Billing Type | H5: Description | I5: Issue Date | J5: Terms (days) | K5: Due Date | L5: Currency | M5: Subtotal | N5: Tax Rate | O5: Tax Amount | P5: Invoice Total | Q5: Credits Applied | R5: Payments Applied | S5: Balance Due | T5: Workflow Status | U5: Payment Status | V5: Days Overdue | W5: Ageing Bucket | X5: Approved By | Y5: Date Sent | Z5: Repo Path / Link | AA5: Notes
A6: INV-2026-001 | B6: NWB | C6: =IF($B6="","",IFERROR(INDEX(Clients!$B$6:$B$105,MATCH($B6,Clients!$A$6:$A$105,0)),"Client not found")) -> Northwind Bank | D6: cl-nwb-core-migration | E6: QUO-2026-001 | F6: PO-4500123 | G6: Deposit / advance | H6: Deposit: 50% of core migration assessment | I6: 46280 | J6: =IF($A6="","",IFERROR(IF(N(INDEX(Clients!$E$6:$E$105,MATCH($B6,Clients!$A$6:$A$105,0)))>0,INDEX(Clients!$E$6:$E$105,MATCH($B6,Clients!$A$6:$A$105,0)),Dashboard!$B$6),Dashboard!$B$6)) -> 30 | K6: =IF(OR($A6="",$I6=""),"",$I6+$J6) -> 46310 | L6: USD | M6: 24000 | N6: 0.1 | O6: =IF($A6="","",N($M6)*N($N6)) -> 2400 | P6: =IF($A6="","",N($M6)+$O6) -> 26400 | Q6: =IF($A6="","",SUMIFS('Credit Notes'!$F$6:$F$205,'Credit Notes'!$B$6:$B$205,$A6,'Credit Notes'!$H$6:$H$205,"Issued")) -> 0 | R6: =IF($A6="","",SUMIFS(Payments!$I$6:$I$505,Payments!$C$6:$C$505,$A6)) -> 20000 | S6: =IF($A6="","",IF($T6="Void",0,$P6-$Q6-$R6)) -> 6400 | T6: Issued | U6: =IF($A6="","",IF($T6="Void","Void",IF(OR($T6="",$T6="Draft"),"Draft",IF($T6="Disputed","Disputed",IF($S6<-0.005,"Overpaid",IF($S6<=0.005,"Paid",IF($R6+$Q6>0.005,IF($V6>0,"Part-paid, overdue","Part-paid"),IF($V6>0,"Overdue","Outstanding")))))))) -> Part-paid | V6: =IF($A6="","",IF(AND(OR($T6="Issued",$T6="Disputed"),$S6>0.005,$K6<>"",$K6<TODAY()),TODAY()-$K6,0)) -> 0 | W6: =IF($A6="","",IF(AND(OR($T6="Issued",$T6="Disputed"),$S6>0.005),IF($V6<=0,"Not yet due",IF($V6<=30,"1 to 30 days",IF($V6<=60,"31 to 60 days",IF($V6<=90,"61 to 90 days","Over 90 days")))),"")) -> Not yet due | X6: Jane Doe | Y6: 46280 | Z6: billing/invoices/2026/INV-2026-001-nwb-deposit.md | AA6: EXAMPLE ROW: overwrite with your first real entry. Tax rate is an example value only.
C7: =IF($B7="","",IFERROR(INDEX(Clients!$B$6:$B$105,MATCH($B7,Clients!$A$6:$A$105,0)),"Client not found")) | J7: =IF($A7="","",IFERROR(IF(N(INDEX(Clients!$E$6:$E$105,MATCH($B7,Clients!$A$6:$A$105,0)))>0,INDEX(Clients!$E$6:$E$105,MATCH($B7,Clients!$A$6:$A$105,0)),Dashboard!$B$6),Dashboard!$B$6)) | K7: =IF(OR($A7="",$I7=""),"",$I7+$J7) | O7: =IF($A7="","",N($M7)*N($N7)) | P7: =IF($A7="","",N($M7)+$O7) | Q7: =IF($A7="","",SUMIFS('Credit Notes'!$F$6:$F$205,'Credit Notes'!$B$6:$B$205,$A7,'Credit Notes'!$H$6:$H$205,"Issued")) | R7: =IF($A7="","",SUMIFS(Payments!$I$6:$I$505,Payments!$C$6:$C$505,$A7)) | S7: =IF($A7="","",IF($T7="Void",0,$P7-$Q7-$R7)) | U7: =IF($A7="","",IF($T7="Void","Void",IF(OR($T7="",$T7="Draft"),"Draft",IF($T7="Disputed","Disputed",IF($S7<-0.005,"Overpaid",IF($S7<=0.005,"Paid",IF($R7+$Q7>0.005,IF($V7>0,"Part-paid, overdue","Part-paid"),IF($V7>0,"Overdue","Outstanding")))))))) | V7: =IF($A7="","",IF(AND(OR($T7="Issued",$T7="Disputed"),$S7>0.005,$K7<>"",$K7<TODAY()),TODAY()-$K7,0)) | W7: =IF($A7="","",IF(AND(OR($T7="Issued",$T7="Disputed"),$S7>0.005),IF($V7<=0,"Not yet due",IF($V7<=30,"1 to 30 days",IF($V7<=60,"31 to 60 days",IF($V7<=90,"61 to 90 days","Over 90 days")))),""))
C8: =IF($B8="","",IFERROR(INDEX(Clients!$B$6:$B$105,MATCH($B8,Clients!$A$6:$A$105,0)),"Client not found")) | J8: =IF($A8="","",IFERROR(IF(N(INDEX(Clients!$E$6:$E$105,MATCH($B8,Clients!$A$6:$A$105,0)))>0,INDEX(Clients!$E$6:$E$105,MATCH($B8,Clients!$A$6:$A$105,0)),Dashboard!$B$6),Dashboard!$B$6)) | K8: =IF(OR($A8="",$I8=""),"",$I8+$J8) | O8: =IF($A8="","",N($M8)*N($N8)) | P8: =IF($A8="","",N($M8)+$O8) | Q8: =IF($A8="","",SUMIFS('Credit Notes'!$F$6:$F$205,'Credit Notes'!$B$6:$B$205,$A8,'Credit Notes'!$H$6:$H$205,"Issued")) | R8: =IF($A8="","",SUMIFS(Payments!$I$6:$I$505,Payments!$C$6:$C$505,$A8)) | S8: =IF($A8="","",IF($T8="Void",0,$P8-$Q8-$R8)) | U8: =IF($A8="","",IF($T8="Void","Void",IF(OR($T8="",$T8="Draft"),"Draft",IF($T8="Disputed","Disputed",IF($S8<-0.005,"Overpaid",IF($S8<=0.005,"Paid",IF($R8+$Q8>0.005,IF($V8>0,"Part-paid, overdue","Part-paid"),IF($V8>0,"Overdue","Outstanding")))))))) | V8: =IF($A8="","",IF(AND(OR($T8="Issued",$T8="Disputed"),$S8>0.005,$K8<>"",$K8<TODAY()),TODAY()-$K8,0)) | W8: =IF($A8="","",IF(AND(OR($T8="Issued",$T8="Disputed"),$S8>0.005),IF($V8<=0,"Not yet due",IF($V8<=30,"1 to 30 days",IF($V8<=60,"31 to 60 days",IF($V8<=90,"61 to 90 days","Over 90 days")))),""))
C9: =IF($B9="","",IFERROR(INDEX(Clients!$B$6:$B$105,MATCH($B9,Clients!$A$6:$A$105,0)),"Client not found")) | J9: =IF($A9="","",IFERROR(IF(N(INDEX(Clients!$E$6:$E$105,MATCH($B9,Clients!$A$6:$A$105,0)))>0,INDEX(Clients!$E$6:$E$105,MATCH($B9,Clients!$A$6:$A$105,0)),Dashboard!$B$6),Dashboard!$B$6)) | K9: =IF(OR($A9="",$I9=""),"",$I9+$J9) | O9: =IF($A9="","",N($M9)*N($N9)) | P9: =IF($A9="","",N($M9)+$O9) | Q9: =IF($A9="","",SUMIFS('Credit Notes'!$F$6:$F$205,'Credit Notes'!$B$6:$B$205,$A9,'Credit Notes'!$H$6:$H$205,"Issued")) | R9: =IF($A9="","",SUMIFS(Payments!$I$6:$I$505,Payments!$C$6:$C$505,$A9)) | S9: =IF($A9="","",IF($T9="Void",0,$P9-$Q9-$R9)) | U9: =IF($A9="","",IF($T9="Void","Void",IF(OR($T9="",$T9="Draft"),"Draft",IF($T9="Disputed","Disputed",IF($S9<-0.005,"Overpaid",IF($S9<=0.005,"Paid",IF($R9+$Q9>0.005,IF($V9>0,"Part-paid, overdue","Part-paid"),IF($V9>0,"Overdue","Outstanding")))))))) | V9: =IF($A9="","",IF(AND(OR($T9="Issued",$T9="Disputed"),$S9>0.005,$K9<>"",$K9<TODAY()),TODAY()-$K9,0)) | W9: =IF($A9="","",IF(AND(OR($T9="Issued",$T9="Disputed"),$S9>0.005),IF($V9<=0,"Not yet due",IF($V9<=30,"1 to 30 days",IF($V9<=60,"31 to 60 days",IF($V9<=90,"61 to 90 days","Over 90 days")))),""))
C10: =IF($B10="","",IFERROR(INDEX(Clients!$B$6:$B$105,MATCH($B10,Clients!$A$6:$A$105,0)),"Client not found")) | J10: =IF($A10="","",IFERROR(IF(N(INDEX(Clients!$E$6:$E$105,MATCH($B10,Clients!$A$6:$A$105,0)))>0,INDEX(Clients!$E$6:$E$105,MATCH($B10,Clients!$A$6:$A$105,0)),Dashboard!$B$6),Dashboard!$B$6)) | K10: =IF(OR($A10="",$I10=""),"",$I10+$J10) | O10: =IF($A10="","",N($M10)*N($N10)) | P10: =IF($A10="","",N($M10)+$O10) | Q10: =IF($A10="","",SUMIFS('Credit Notes'!$F$6:$F$205,'Credit Notes'!$B$6:$B$205,$A10,'Credit Notes'!$H$6:$H$205,"Issued")) | R10: =IF($A10="","",SUMIFS(Payments!$I$6:$I$505,Payments!$C$6:$C$505,$A10)) | S10: =IF($A10="","",IF($T10="Void",0,$P10-$Q10-$R10)) | U10: =IF($A10="","",IF($T10="Void","Void",IF(OR($T10="",$T10="Draft"),"Draft",IF($T10="Disputed","Disputed",IF($S10<-0.005,"Overpaid",IF($S10<=0.005,"Paid",IF($R10+$Q10>0.005,IF($V10>0,"Part-paid, overdue","Part-paid"),IF($V10>0,"Overdue","Outstanding")))))))) | V10: =IF($A10="","",IF(AND(OR($T10="Issued",$T10="Disputed"),$S10>0.005,$K10<>"",$K10<TODAY()),TODAY()-$K10,0)) | W10: =IF($A10="","",IF(AND(OR($T10="Issued",$T10="Disputed"),$S10>0.005),IF($V10<=0,"Not yet due",IF($V10<=30,"1 to 30 days",IF($V10<=60,"31 to 60 days",IF($V10<=90,"61 to 90 days","Over 90 days")))),""))
C11: =IF($B11="","",IFERROR(INDEX(Clients!$B$6:$B$105,MATCH($B11,Clients!$A$6:$A$105,0)),"Client not found")) | J11: =IF($A11="","",IFERROR(IF(N(INDEX(Clients!$E$6:$E$105,MATCH($B11,Clients!$A$6:$A$105,0)))>0,INDEX(Clients!$E$6:$E$105,MATCH($B11,Clients!$A$6:$A$105,0)),Dashboard!$B$6),Dashboard!$B$6)) | K11: =IF(OR($A11="",$I11=""),"",$I11+$J11) | O11: =IF($A11="","",N($M11)*N($N11)) | P11: =IF($A11="","",N($M11)+$O11) | Q11: =IF($A11="","",SUMIFS('Credit Notes'!$F$6:$F$205,'Credit Notes'!$B$6:$B$205,$A11,'Credit Notes'!$H$6:$H$205,"Issued")) | R11: =IF($A11="","",SUMIFS(Payments!$I$6:$I$505,Payments!$C$6:$C$505,$A11)) | S11: =IF($A11="","",IF($T11="Void",0,$P11-$Q11-$R11)) | U11: =IF($A11="","",IF($T11="Void","Void",IF(OR($T11="",$T11="Draft"),"Draft",IF($T11="Disputed","Disputed",IF($S11<-0.005,"Overpaid",IF($S11<=0.005,"Paid",IF($R11+$Q11>0.005,IF($V11>0,"Part-paid, overdue","Part-paid"),IF($V11>0,"Overdue","Outstanding")))))))) | V11: =IF($A11="","",IF(AND(OR($T11="Issued",$T11="Disputed"),$S11>0.005,$K11<>"",$K11<TODAY()),TODAY()-$K11,0)) | W11: =IF($A11="","",IF(AND(OR($T11="Issued",$T11="Disputed"),$S11>0.005),IF($V11<=0,"Not yet due",IF($V11<=30,"1 to 30 days",IF($V11<=60,"31 to 60 days",IF($V11<=90,"61 to 90 days","Over 90 days")))),""))
C12: =IF($B12="","",IFERROR(INDEX(Clients!$B$6:$B$105,MATCH($B12,Clients!$A$6:$A$105,0)),"Client not found")) | J12: =IF($A12="","",IFERROR(IF(N(INDEX(Clients!$E$6:$E$105,MATCH($B12,Clients!$A$6:$A$105,0)))>0,INDEX(Clients!$E$6:$E$105,MATCH($B12,Clients!$A$6:$A$105,0)),Dashboard!$B$6),Dashboard!$B$6)) | K12: =IF(OR($A12="",$I12=""),"",$I12+$J12) | O12: =IF($A12="","",N($M12)*N($N12)) | P12: =IF($A12="","",N($M12)+$O12) | Q12: =IF($A12="","",SUMIFS('Credit Notes'!$F$6:$F$205,'Credit Notes'!$B$6:$B$205,$A12,'Credit Notes'!$H$6:$H$205,"Issued")) | R12: =IF($A12="","",SUMIFS(Payments!$I$6:$I$505,Payments!$C$6:$C$505,$A12)) | S12: =IF($A12="","",IF($T12="Void",0,$P12-$Q12-$R12)) | U12: =IF($A12="","",IF($T12="Void","Void",IF(OR($T12="",$T12="Draft"),"Draft",IF($T12="Disputed","Disputed",IF($S12<-0.005,"Overpaid",IF($S12<=0.005,"Paid",IF($R12+$Q12>0.005,IF($V12>0,"Part-paid, overdue","Part-paid"),IF($V12>0,"Overdue","Outstanding")))))))) | V12: =IF($A12="","",IF(AND(OR($T12="Issued",$T12="Disputed"),$S12>0.005,$K12<>"",$K12<TODAY()),TODAY()-$K12,0)) | W12: =IF($A12="","",IF(AND(OR($T12="Issued",$T12="Disputed"),$S12>0.005),IF($V12<=0,"Not yet due",IF($V12<=30,"1 to 30 days",IF($V12<=60,"31 to 60 days",IF($V12<=90,"61 to 90 days","Over 90 days")))),""))
C13: =IF($B13="","",IFERROR(INDEX(Clients!$B$6:$B$105,MATCH($B13,Clients!$A$6:$A$105,0)),"Client not found")) | J13: =IF($A13="","",IFERROR(IF(N(INDEX(Clients!$E$6:$E$105,MATCH($B13,Clients!$A$6:$A$105,0)))>0,INDEX(Clients!$E$6:$E$105,MATCH($B13,Clients!$A$6:$A$105,0)),Dashboard!$B$6),Dashboard!$B$6)) | K13: =IF(OR($A13="",$I13=""),"",$I13+$J13) | O13: =IF($A13="","",N($M13)*N($N13)) | P13: =IF($A13="","",N($M13)+$O13) | Q13: =IF($A13="","",SUMIFS('Credit Notes'!$F$6:$F$205,'Credit Notes'!$B$6:$B$205,$A13,'Credit Notes'!$H$6:$H$205,"Issued")) | R13: =IF($A13="","",SUMIFS(Payments!$I$6:$I$505,Payments!$C$6:$C$505,$A13)) | S13: =IF($A13="","",IF($T13="Void",0,$P13-$Q13-$R13)) | U13: =IF($A13="","",IF($T13="Void","Void",IF(OR($T13="",$T13="Draft"),"Draft",IF($T13="Disputed","Disputed",IF($S13<-0.005,"Overpaid",IF($S13<=0.005,"Paid",IF($R13+$Q13>0.005,IF($V13>0,"Part-paid, overdue","Part-paid"),IF($V13>0,"Overdue","Outstanding")))))))) | V13: =IF($A13="","",IF(AND(OR($T13="Issued",$T13="Disputed"),$S13>0.005,$K13<>"",$K13<TODAY()),TODAY()-$K13,0)) | W13: =IF($A13="","",IF(AND(OR($T13="Issued",$T13="Disputed"),$S13>0.005),IF($V13<=0,"Not yet due",IF($V13<=30,"1 to 30 days",IF($V13<=60,"31 to 60 days",IF($V13<=90,"61 to 90 days","Over 90 days")))),""))
C14: =IF($B14="","",IFERROR(INDEX(Clients!$B$6:$B$105,MATCH($B14,Clients!$A$6:$A$105,0)),"Client not found")) | J14: =IF($A14="","",IFERROR(IF(N(INDEX(Clients!$E$6:$E$105,MATCH($B14,Clients!$A$6:$A$105,0)))>0,INDEX(Clients!$E$6:$E$105,MATCH($B14,Clients!$A$6:$A$105,0)),Dashboard!$B$6),Dashboard!$B$6)) | K14: =IF(OR($A14="",$I14=""),"",$I14+$J14) | O14: =IF($A14="","",N($M14)*N($N14)) | P14: =IF($A14="","",N($M14)+$O14) | Q14: =IF($A14="","",SUMIFS('Credit Notes'!$F$6:$F$205,'Credit Notes'!$B$6:$B$205,$A14,'Credit Notes'!$H$6:$H$205,"Issued")) | R14: =IF($A14="","",SUMIFS(Payments!$I$6:$I$505,Payments!$C$6:$C$505,$A14)) | S14: =IF($A14="","",IF($T14="Void",0,$P14-$Q14-$R14)) | U14: =IF($A14="","",IF($T14="Void","Void",IF(OR($T14="",$T14="Draft"),"Draft",IF($T14="Disputed","Disputed",IF($S14<-0.005,"Overpaid",IF($S14<=0.005,"Paid",IF($R14+$Q14>0.005,IF($V14>0,"Part-paid, overdue","Part-paid"),IF($V14>0,"Overdue","Outstanding")))))))) | V14: =IF($A14="","",IF(AND(OR($T14="Issued",$T14="Disputed"),$S14>0.005,$K14<>"",$K14<TODAY()),TODAY()-$K14,0)) | W14: =IF($A14="","",IF(AND(OR($T14="Issued",$T14="Disputed"),$S14>0.005),IF($V14<=0,"Not yet due",IF($V14<=30,"1 to 30 days",IF($V14<=60,"31 to 60 days",IF($V14<=90,"61 to 90 days","Over 90 days")))),""))
C15: =IF($B15="","",IFERROR(INDEX(Clients!$B$6:$B$105,MATCH($B15,Clients!$A$6:$A$105,0)),"Client not found")) | J15: =IF($A15="","",IFERROR(IF(N(INDEX(Clients!$E$6:$E$105,MATCH($B15,Clients!$A$6:$A$105,0)))>0,INDEX(Clients!$E$6:$E$105,MATCH($B15,Clients!$A$6:$A$105,0)),Dashboard!$B$6),Dashboard!$B$6)) | K15: =IF(OR($A15="",$I15=""),"",$I15+$J15) | O15: =IF($A15="","",N($M15)*N($N15)) | P15: =IF($A15="","",N($M15)+$O15) | Q15: =IF($A15="","",SUMIFS('Credit Notes'!$F$6:$F$205,'Credit Notes'!$B$6:$B$205,$A15,'Credit Notes'!$H$6:$H$205,"Issued")) | R15: =IF($A15="","",SUMIFS(Payments!$I$6:$I$505,Payments!$C$6:$C$505,$A15)) | S15: =IF($A15="","",IF($T15="Void",0,$P15-$Q15-$R15)) | U15: =IF($A15="","",IF($T15="Void","Void",IF(OR($T15="",$T15="Draft"),"Draft",IF($T15="Disputed","Disputed",IF($S15<-0.005,"Overpaid",IF($S15<=0.005,"Paid",IF($R15+$Q15>0.005,IF($V15>0,"Part-paid, overdue","Part-paid"),IF($V15>0,"Overdue","Outstanding")))))))) | V15: =IF($A15="","",IF(AND(OR($T15="Issued",$T15="Disputed"),$S15>0.005,$K15<>"",$K15<TODAY()),TODAY()-$K15,0)) | W15: =IF($A15="","",IF(AND(OR($T15="Issued",$T15="Disputed"),$S15>0.005),IF($V15<=0,"Not yet due",IF($V15<=30,"1 to 30 days",IF($V15<=60,"31 to 60 days",IF($V15<=90,"61 to 90 days","Over 90 days")))),""))
C16: =IF($B16="","",IFERROR(INDEX(Clients!$B$6:$B$105,MATCH($B16,Clients!$A$6:$A$105,0)),"Client not found")) | J16: =IF($A16="","",IFERROR(IF(N(INDEX(Clients!$E$6:$E$105,MATCH($B16,Clients!$A$6:$A$105,0)))>0,INDEX(Clients!$E$6:$E$105,MATCH($B16,Clients!$A$6:$A$105,0)),Dashboard!$B$6),Dashboard!$B$6)) | K16: =IF(OR($A16="",$I16=""),"",$I16+$J16) | O16: =IF($A16="","",N($M16)*N($N16)) | P16: =IF($A16="","",N($M16)+$O16) | Q16: =IF($A16="","",SUMIFS('Credit Notes'!$F$6:$F$205,'Credit Notes'!$B$6:$B$205,$A16,'Credit Notes'!$H$6:$H$205,"Issued")) | R16: =IF($A16="","",SUMIFS(Payments!$I$6:$I$505,Payments!$C$6:$C$505,$A16)) | S16: =IF($A16="","",IF($T16="Void",0,$P16-$Q16-$R16)) | U16: =IF($A16="","",IF($T16="Void","Void",IF(OR($T16="",$T16="Draft"),"Draft",IF($T16="Disputed","Disputed",IF($S16<-0.005,"Overpaid",IF($S16<=0.005,"Paid",IF($R16+$Q16>0.005,IF($V16>0,"Part-paid, overdue","Part-paid"),IF($V16>0,"Overdue","Outstanding")))))))) | V16: =IF($A16="","",IF(AND(OR($T16="Issued",$T16="Disputed"),$S16>0.005,$K16<>"",$K16<TODAY()),TODAY()-$K16,0)) | W16: =IF($A16="","",IF(AND(OR($T16="Issued",$T16="Disputed"),$S16>0.005),IF($V16<=0,"Not yet due",IF($V16<=30,"1 to 30 days",IF($V16<=60,"31 to 60 days",IF($V16<=90,"61 to 90 days","Over 90 days")))),""))
C17: =IF($B17="","",IFERROR(INDEX(Clients!$B$6:$B$105,MATCH($B17,Clients!$A$6:$A$105,0)),"Client not found")) | J17: =IF($A17="","",IFERROR(IF(N(INDEX(Clients!$E$6:$E$105,MATCH($B17,Clients!$A$6:$A$105,0)))>0,INDEX(Clients!$E$6:$E$105,MATCH($B17,Clients!$A$6:$A$105,0)),Dashboard!$B$6),Dashboard!$B$6)) | K17: =IF(OR($A17="",$I17=""),"",$I17+$J17) | O17: =IF($A17="","",N($M17)*N($N17)) | P17: =IF($A17="","",N($M17)+$O17) | Q17: =IF($A17="","",SUMIFS('Credit Notes'!$F$6:$F$205,'Credit Notes'!$B$6:$B$205,$A17,'Credit Notes'!$H$6:$H$205,"Issued")) | R17: =IF($A17="","",SUMIFS(Payments!$I$6:$I$505,Payments!$C$6:$C$505,$A17)) | S17: =IF($A17="","",IF($T17="Void",0,$P17-$Q17-$R17)) | U17: =IF($A17="","",IF($T17="Void","Void",IF(OR($T17="",$T17="Draft"),"Draft",IF($T17="Disputed","Disputed",IF($S17<-0.005,"Overpaid",IF($S17<=0.005,"Paid",IF($R17+$Q17>0.005,IF($V17>0,"Part-paid, overdue","Part-paid"),IF($V17>0,"Overdue","Outstanding")))))))) | V17: =IF($A17="","",IF(AND(OR($T17="Issued",$T17="Disputed"),$S17>0.005,$K17<>"",$K17<TODAY()),TODAY()-$K17,0)) | W17: =IF($A17="","",IF(AND(OR($T17="Issued",$T17="Disputed"),$S17>0.005),IF($V17<=0,"Not yet due",IF($V17<=30,"1 to 30 days",IF($V17<=60,"31 to 60 days",IF($V17<=90,"61 to 90 days","Over 90 days")))),""))
C18: =IF($B18="","",IFERROR(INDEX(Clients!$B$6:$B$105,MATCH($B18,Clients!$A$6:$A$105,0)),"Client not found")) | J18: =IF($A18="","",IFERROR(IF(N(INDEX(Clients!$E$6:$E$105,MATCH($B18,Clients!$A$6:$A$105,0)))>0,INDEX(Clients!$E$6:$E$105,MATCH($B18,Clients!$A$6:$A$105,0)),Dashboard!$B$6),Dashboard!$B$6)) | K18: =IF(OR($A18="",$I18=""),"",$I18+$J18) | O18: =IF($A18="","",N($M18)*N($N18)) | P18: =IF($A18="","",N($M18)+$O18) | Q18: =IF($A18="","",SUMIFS('Credit Notes'!$F$6:$F$205,'Credit Notes'!$B$6:$B$205,$A18,'Credit Notes'!$H$6:$H$205,"Issued")) | R18: =IF($A18="","",SUMIFS(Payments!$I$6:$I$505,Payments!$C$6:$C$505,$A18)) | S18: =IF($A18="","",IF($T18="Void",0,$P18-$Q18-$R18)) | U18: =IF($A18="","",IF($T18="Void","Void",IF(OR($T18="",$T18="Draft"),"Draft",IF($T18="Disputed","Disputed",IF($S18<-0.005,"Overpaid",IF($S18<=0.005,"Paid",IF($R18+$Q18>0.005,IF($V18>0,"Part-paid, overdue","Part-paid"),IF($V18>0,"Overdue","Outstanding")))))))) | V18: =IF($A18="","",IF(AND(OR($T18="Issued",$T18="Disputed"),$S18>0.005,$K18<>"",$K18<TODAY()),TODAY()-$K18,0)) | W18: =IF($A18="","",IF(AND(OR($T18="Issued",$T18="Disputed"),$S18>0.005),IF($V18<=0,"Not yet due",IF($V18<=30,"1 to 30 days",IF($V18<=60,"31 to 60 days",IF($V18<=90,"61 to 90 days","Over 90 days")))),""))
... C505: =IF($B505="","",IFERROR(INDEX(Clients!$B$6:$B$105,MATCH($B505,Clients!$A$6:$A$105,0)),"Client not found")) | J505: =IF($A505="","",IFERROR(IF(N(INDEX(Clients!$E$6:$E$105,MATCH($B505,Clients!$A$6:$A$105,0)))>0,INDEX(Clients!$E$6:$E$105,MATCH($B505,Clients!$A$6:$A$105,0)),Dashboard!$B$6),Dashboard!$B$6)) | K505: =IF(OR($A505="",$I505=""),"",$I505+$J505) | O505: =IF($A505="","",N($M505)*N($N505)) | P505: =IF($A505="","",N($M505)+$O505) | Q505: =IF($A505="","",SUMIFS('Credit Notes'!$F$6:$F$205,'Credit Notes'!$B$6:$B$205,$A505,'Credit Notes'!$H$6:$H$205,"Issued")) | R505: =IF($A505="","",SUMIFS(Payments!$I$6:$I$505,Payments!$C$6:$C$505,$A505)) | S505: =IF($A505="","",IF($T505="Void",0,$P505-$Q505-$R505)) | U505: =IF($A505="","",IF($T505="Void","Void",IF(OR($T505="",$T505="Draft"),"Draft",IF($T505="Disputed","Disputed",IF($S505<-0.005,"Overpaid",IF($S505<=0.005,"Paid",IF($R505+$Q505>0.005,IF($V505>0,"Part-paid, overdue","Part-paid"),IF($V505>0,"Overdue","Outstanding")))))))) | V505: =IF($A505="","",IF(AND(OR($T505="Issued",$T505="Disputed"),$S505>0.005,$K505<>"",$K505<TODAY()),TODAY()-$K505,0)) | W505: =IF($A505="","",IF(AND(OR($T505="Issued",$T505="Disputed"),$S505>0.005),IF($V505<=0,"Not yet due",IF($V505<=30,"1 to 30 days",IF($V505<=60,"31 to 60 days",IF($V505<=90,"61 to 90 days","Over 90 days")))),""))

Sheet Payments
A1: Knotica Solutions Inc: Payment Register
A2: One row per payment received. IDs follow RCT-YYYY-###. Never delete rows. Never record bank account or card numbers.
A3: Blue = type here | Black on grey = formula (do not edit) | Yellow = may be overridden
A5: Payment ID | B5: Date Received | C5: Invoice ID | D5: Client Name | E5: Currency | F5: Amount Received | G5: Tax Withheld by Client | H5: Bank Charges / Short Payment Absorbed | I5: Amount Applied to Invoice | J5: Method | K5: Bank / Remittance Reference | L5: Withholding Certificate | M5: Recorded By | N5: Repo Path / Link | O5: Notes
A6: RCT-2026-001 | B6: 46293 | C6: INV-2026-001 | D6: =IF($C6="","",IFERROR(INDEX(Invoices!$C$6:$C$505,MATCH($C6,Invoices!$A$6:$A$505,0)),"Invoice not found")) -> Northwind Bank | E6: =IF($C6="","",IFERROR(INDEX(Invoices!$L$6:$L$505,MATCH($C6,Invoices!$A$6:$A$505,0)),"")) -> USD | F6: 20000 | I6: =IF($A6="","",N($F6)+N($G6)+N($H6)) -> 20000 | J6: Bank transfer | K6: REMIT-88231 | L6: Not applicable | M6: Jane Doe | N6: billing/payments/2026/RCT-2026-001-nwb-deposit.md | O6: EXAMPLE ROW: overwrite with your first real entry. Part payment: balance stays open.
D7: =IF($C7="","",IFERROR(INDEX(Invoices!$C$6:$C$505,MATCH($C7,Invoices!$A$6:$A$505,0)),"Invoice not found")) | E7: =IF($C7="","",IFERROR(INDEX(Invoices!$L$6:$L$505,MATCH($C7,Invoices!$A$6:$A$505,0)),"")) | I7: =IF($A7="","",N($F7)+N($G7)+N($H7))
D8: =IF($C8="","",IFERROR(INDEX(Invoices!$C$6:$C$505,MATCH($C8,Invoices!$A$6:$A$505,0)),"Invoice not found")) | E8: =IF($C8="","",IFERROR(INDEX(Invoices!$L$6:$L$505,MATCH($C8,Invoices!$A$6:$A$505,0)),"")) | I8: =IF($A8="","",N($F8)+N($G8)+N($H8))
D9: =IF($C9="","",IFERROR(INDEX(Invoices!$C$6:$C$505,MATCH($C9,Invoices!$A$6:$A$505,0)),"Invoice not found")) | E9: =IF($C9="","",IFERROR(INDEX(Invoices!$L$6:$L$505,MATCH($C9,Invoices!$A$6:$A$505,0)),"")) | I9: =IF($A9="","",N($F9)+N($G9)+N($H9))
D10: =IF($C10="","",IFERROR(INDEX(Invoices!$C$6:$C$505,MATCH($C10,Invoices!$A$6:$A$505,0)),"Invoice not found")) | E10: =IF($C10="","",IFERROR(INDEX(Invoices!$L$6:$L$505,MATCH($C10,Invoices!$A$6:$A$505,0)),"")) | I10: =IF($A10="","",N($F10)+N($G10)+N($H10))
D11: =IF($C11="","",IFERROR(INDEX(Invoices!$C$6:$C$505,MATCH($C11,Invoices!$A$6:$A$505,0)),"Invoice not found")) | E11: =IF($C11="","",IFERROR(INDEX(Invoices!$L$6:$L$505,MATCH($C11,Invoices!$A$6:$A$505,0)),"")) | I11: =IF($A11="","",N($F11)+N($G11)+N($H11))
D12: =IF($C12="","",IFERROR(INDEX(Invoices!$C$6:$C$505,MATCH($C12,Invoices!$A$6:$A$505,0)),"Invoice not found")) | E12: =IF($C12="","",IFERROR(INDEX(Invoices!$L$6:$L$505,MATCH($C12,Invoices!$A$6:$A$505,0)),"")) | I12: =IF($A12="","",N($F12)+N($G12)+N($H12))
D13: =IF($C13="","",IFERROR(INDEX(Invoices!$C$6:$C$505,MATCH($C13,Invoices!$A$6:$A$505,0)),"Invoice not found")) | E13: =IF($C13="","",IFERROR(INDEX(Invoices!$L$6:$L$505,MATCH($C13,Invoices!$A$6:$A$505,0)),"")) | I13: =IF($A13="","",N($F13)+N($G13)+N($H13))
D14: =IF($C14="","",IFERROR(INDEX(Invoices!$C$6:$C$505,MATCH($C14,Invoices!$A$6:$A$505,0)),"Invoice not found")) | E14: =IF($C14="","",IFERROR(INDEX(Invoices!$L$6:$L$505,MATCH($C14,Invoices!$A$6:$A$505,0)),"")) | I14: =IF($A14="","",N($F14)+N($G14)+N($H14))
D15: =IF($C15="","",IFERROR(INDEX(Invoices!$C$6:$C$505,MATCH($C15,Invoices!$A$6:$A$505,0)),"Invoice not found")) | E15: =IF($C15="","",IFERROR(INDEX(Invoices!$L$6:$L$505,MATCH($C15,Invoices!$A$6:$A$505,0)),"")) | I15: =IF($A15="","",N($F15)+N($G15)+N($H15))
D16: =IF($C16="","",IFERROR(INDEX(Invoices!$C$6:$C$505,MATCH($C16,Invoices!$A$6:$A$505,0)),"Invoice not found")) | E16: =IF($C16="","",IFERROR(INDEX(Invoices!$L$6:$L$505,MATCH($C16,Invoices!$A$6:$A$505,0)),"")) | I16: =IF($A16="","",N($F16)+N($G16)+N($H16))
D17: =IF($C17="","",IFERROR(INDEX(Invoices!$C$6:$C$505,MATCH($C17,Invoices!$A$6:$A$505,0)),"Invoice not found")) | E17: =IF($C17="","",IFERROR(INDEX(Invoices!$L$6:$L$505,MATCH($C17,Invoices!$A$6:$A$505,0)),"")) | I17: =IF($A17="","",N($F17)+N($G17)+N($H17))
D18: =IF($C18="","",IFERROR(INDEX(Invoices!$C$6:$C$505,MATCH($C18,Invoices!$A$6:$A$505,0)),"Invoice not found")) | E18: =IF($C18="","",IFERROR(INDEX(Invoices!$L$6:$L$505,MATCH($C18,Invoices!$A$6:$A$505,0)),"")) | I18: =IF($A18="","",N($F18)+N($G18)+N($H18))
... D505: =IF($C505="","",IFERROR(INDEX(Invoices!$C$6:$C$505,MATCH($C505,Invoices!$A$6:$A$505,0)),"Invoice not found")) | E505: =IF($C505="","",IFERROR(INDEX(Invoices!$L$6:$L$505,MATCH($C505,Invoices!$A$6:$A$505,0)),"")) | I505: =IF($A505="","",N($F505)+N($G505)+N($H505))

Sheet Credit Notes
A1: Knotica Solutions Inc: Credit Note Register
A2: One row per credit note. IDs follow CN-YYYY-###. A credit note reduces an invoice balance only when its Status is Issued.
A3: Blue = type here | Black on grey = formula (do not edit) | Yellow = may be overridden
A5: Credit Note ID | B5: Related Invoice ID | C5: Client Name | D5: Date Issued | E5: Currency | F5: Credit Amount (incl. tax) | G5: Reason | H5: Status | I5: Approved By | J5: Repo Path / Link | K5: Notes
A6: CN-2026-001 | B6: INV-2026-001 | C6: =IF($B6="","",IFERROR(INDEX(Invoices!$C$6:$C$505,MATCH($B6,Invoices!$A$6:$A$505,0)),"Invoice not found")) -> Northwind Bank | D6: 46295 | E6: =IF($B6="","",IFERROR(INDEX(Invoices!$L$6:$L$505,MATCH($B6,Invoices!$A$6:$A$505,0)),"")) -> USD | F6: 1000 | G6: Service credit (SLA) | H6: Draft | J6: billing/credit-notes/2026/CN-2026-001-nwb-service-credit.md | K6: EXAMPLE ROW: overwrite with your first real entry. Status Draft, so it does not reduce the balance yet.
C7: =IF($B7="","",IFERROR(INDEX(Invoices!$C$6:$C$505,MATCH($B7,Invoices!$A$6:$A$505,0)),"Invoice not found")) | E7: =IF($B7="","",IFERROR(INDEX(Invoices!$L$6:$L$505,MATCH($B7,Invoices!$A$6:$A$505,0)),""))
C8: =IF($B8="","",IFERROR(INDEX(Invoices!$C$6:$C$505,MATCH($B8,Invoices!$A$6:$A$505,0)),"Invoice not found")) | E8: =IF($B8="","",IFERROR(INDEX(Invoices!$L$6:$L$505,MATCH($B8,Invoices!$A$6:$A$505,0)),""))
C9: =IF($B9="","",IFERROR(INDEX(Invoices!$C$6:$C$505,MATCH($B9,Invoices!$A$6:$A$505,0)),"Invoice not found")) | E9: =IF($B9="","",IFERROR(INDEX(Invoices!$L$6:$L$505,MATCH($B9,Invoices!$A$6:$A$505,0)),""))
C10: =IF($B10="","",IFERROR(INDEX(Invoices!$C$6:$C$505,MATCH($B10,Invoices!$A$6:$A$505,0)),"Invoice not found")) | E10: =IF($B10="","",IFERROR(INDEX(Invoices!$L$6:$L$505,MATCH($B10,Invoices!$A$6:$A$505,0)),""))
C11: =IF($B11="","",IFERROR(INDEX(Invoices!$C$6:$C$505,MATCH($B11,Invoices!$A$6:$A$505,0)),"Invoice not found")) | E11: =IF($B11="","",IFERROR(INDEX(Invoices!$L$6:$L$505,MATCH($B11,Invoices!$A$6:$A$505,0)),""))
C12: =IF($B12="","",IFERROR(INDEX(Invoices!$C$6:$C$505,MATCH($B12,Invoices!$A$6:$A$505,0)),"Invoice not found")) | E12: =IF($B12="","",IFERROR(INDEX(Invoices!$L$6:$L$505,MATCH($B12,Invoices!$A$6:$A$505,0)),""))
C13: =IF($B13="","",IFERROR(INDEX(Invoices!$C$6:$C$505,MATCH($B13,Invoices!$A$6:$A$505,0)),"Invoice not found")) | E13: =IF($B13="","",IFERROR(INDEX(Invoices!$L$6:$L$505,MATCH($B13,Invoices!$A$6:$A$505,0)),""))
C14: =IF($B14="","",IFERROR(INDEX(Invoices!$C$6:$C$505,MATCH($B14,Invoices!$A$6:$A$505,0)),"Invoice not found")) | E14: =IF($B14="","",IFERROR(INDEX(Invoices!$L$6:$L$505,MATCH($B14,Invoices!$A$6:$A$505,0)),""))
C15: =IF($B15="","",IFERROR(INDEX(Invoices!$C$6:$C$505,MATCH($B15,Invoices!$A$6:$A$505,0)),"Invoice not found")) | E15: =IF($B15="","",IFERROR(INDEX(Invoices!$L$6:$L$505,MATCH($B15,Invoices!$A$6:$A$505,0)),""))
C16: =IF($B16="","",IFERROR(INDEX(Invoices!$C$6:$C$505,MATCH($B16,Invoices!$A$6:$A$505,0)),"Invoice not found")) | E16: =IF($B16="","",IFERROR(INDEX(Invoices!$L$6:$L$505,MATCH($B16,Invoices!$A$6:$A$505,0)),""))
C17: =IF($B17="","",IFERROR(INDEX(Invoices!$C$6:$C$505,MATCH($B17,Invoices!$A$6:$A$505,0)),"Invoice not found")) | E17: =IF($B17="","",IFERROR(INDEX(Invoices!$L$6:$L$505,MATCH($B17,Invoices!$A$6:$A$505,0)),""))
C18: =IF($B18="","",IFERROR(INDEX(Invoices!$C$6:$C$505,MATCH($B18,Invoices!$A$6:$A$505,0)),"Invoice not found")) | E18: =IF($B18="","",IFERROR(INDEX(Invoices!$L$6:$L$505,MATCH($B18,Invoices!$A$6:$A$505,0)),""))
... C205: =IF($B205="","",IFERROR(INDEX(Invoices!$C$6:$C$505,MATCH($B205,Invoices!$A$6:$A$505,0)),"Invoice not found")) | E205: =IF($B205="","",IFERROR(INDEX(Invoices!$L$6:$L$505,MATCH($B205,Invoices!$A$6:$A$505,0)),""))

Sheet Clients
A1: Knotica Solutions Inc: Client Billing Profiles
A2: One row per client. Client codes match the Document Register in the sales repo (3 to 5 capital letters, never reused). No bank or card details here.
A3: Blue = type here | Black on grey = formula (do not edit) | Yellow = may be overridden
A5: Client Code | B5: Client Name | C5: Billing Contact (name / role) | D5: Billing Channel | E5: Payment Terms (days) | F5: Default Currency | G5: PO Required? | H5: Billing Status | I5: Tax / Withholding Notes | J5: Invoices Issued | K5: Net Balance Due | L5: Overdue Amount | M5: Notes
A6: NWB | B6: Northwind Bank | C6: Accounts Payable Manager | D6: Email | E6: 30 | F6: USD | G6: Yes | H6: Good standing | I6: Client withholds tax at source: request the certificate with each remittance. | J6: =IF($A6="","",COUNTIFS(Invoices!$B$6:$B$505,$A6,Invoices!$T$6:$T$505,"Issued")+COUNTIFS(Invoices!$B$6:$B$505,$A6,Invoices!$T$6:$T$505,"Disputed")) -> 1 | K6: =IF($A6="","",SUMIFS(Invoices!$S$6:$S$505,Invoices!$B$6:$B$505,$A6,Invoices!$T$6:$T$505,"Issued")+SUMIFS(Invoices!$S$6:$S$505,Invoices!$B$6:$B$505,$A6,Invoices!$T$6:$T$505,"Disputed")) -> 6400 | L6: =IF($A6="","",SUMIFS(Invoices!$S$6:$S$505,Invoices!$B$6:$B$505,$A6,Invoices!$V$6:$V$505,">0")) -> 0 | M6: EXAMPLE ROW: overwrite with your first real client
J7: =IF($A7="","",COUNTIFS(Invoices!$B$6:$B$505,$A7,Invoices!$T$6:$T$505,"Issued")+COUNTIFS(Invoices!$B$6:$B$505,$A7,Invoices!$T$6:$T$505,"Disputed")) | K7: =IF($A7="","",SUMIFS(Invoices!$S$6:$S$505,Invoices!$B$6:$B$505,$A7,Invoices!$T$6:$T$505,"Issued")+SUMIFS(Invoices!$S$6:$S$505,Invoices!$B$6:$B$505,$A7,Invoices!$T$6:$T$505,"Disputed")) | L7: =IF($A7="","",SUMIFS(Invoices!$S$6:$S$505,Invoices!$B$6:$B$505,$A7,Invoices!$V$6:$V$505,">0"))
J8: =IF($A8="","",COUNTIFS(Invoices!$B$6:$B$505,$A8,Invoices!$T$6:$T$505,"Issued")+COUNTIFS(Invoices!$B$6:$B$505,$A8,Invoices!$T$6:$T$505,"Disputed")) | K8: =IF($A8="","",SUMIFS(Invoices!$S$6:$S$505,Invoices!$B$6:$B$505,$A8,Invoices!$T$6:$T$505,"Issued")+SUMIFS(Invoices!$S$6:$S$505,Invoices!$B$6:$B$505,$A8,Invoices!$T$6:$T$505,"Disputed")) | L8: =IF($A8="","",SUMIFS(Invoices!$S$6:$S$505,Invoices!$B$6:$B$505,$A8,Invoices!$V$6:$V$505,">0"))
J9: =IF($A9="","",COUNTIFS(Invoices!$B$6:$B$505,$A9,Invoices!$T$6:$T$505,"Issued")+COUNTIFS(Invoices!$B$6:$B$505,$A9,Invoices!$T$6:$T$505,"Disputed")) | K9: =IF($A9="","",SUMIFS(Invoices!$S$6:$S$505,Invoices!$B$6:$B$505,$A9,Invoices!$T$6:$T$505,"Issued")+SUMIFS(Invoices!$S$6:$S$505,Invoices!$B$6:$B$505,$A9,Invoices!$T$6:$T$505,"Disputed")) | L9: =IF($A9="","",SUMIFS(Invoices!$S$6:$S$505,Invoices!$B$6:$B$505,$A9,Invoices!$V$6:$V$505,">0"))
J10: =IF($A10="","",COUNTIFS(Invoices!$B$6:$B$505,$A10,Invoices!$T$6:$T$505,"Issued")+COUNTIFS(Invoices!$B$6:$B$505,$A10,Invoices!$T$6:$T$505,"Disputed")) | K10: =IF($A10="","",SUMIFS(Invoices!$S$6:$S$505,Invoices!$B$6:$B$505,$A10,Invoices!$T$6:$T$505,"Issued")+SUMIFS(Invoices!$S$6:$S$505,Invoices!$B$6:$B$505,$A10,Invoices!$T$6:$T$505,"Disputed")) | L10: =IF($A10="","",SUMIFS(Invoices!$S$6:$S$505,Invoices!$B$6:$B$505,$A10,Invoices!$V$6:$V$505,">0"))
J11: =IF($A11="","",COUNTIFS(Invoices!$B$6:$B$505,$A11,Invoices!$T$6:$T$505,"Issued")+COUNTIFS(Invoices!$B$6:$B$505,$A11,Invoices!$T$6:$T$505,"Disputed")) | K11: =IF($A11="","",SUMIFS(Invoices!$S$6:$S$505,Invoices!$B$6:$B$505,$A11,Invoices!$T$6:$T$505,"Issued")+SUMIFS(Invoices!$S$6:$S$505,Invoices!$B$6:$B$505,$A11,Invoices!$T$6:$T$505,"Disputed")) | L11: =IF($A11="","",SUMIFS(Invoices!$S$6:$S$505,Invoices!$B$6:$B$505,$A11,Invoices!$V$6:$V$505,">0"))
J12: =IF($A12="","",COUNTIFS(Invoices!$B$6:$B$505,$A12,Invoices!$T$6:$T$505,"Issued")+COUNTIFS(Invoices!$B$6:$B$505,$A12,Invoices!$T$6:$T$505,"Disputed")) | K12: =IF($A12="","",SUMIFS(Invoices!$S$6:$S$505,Invoices!$B$6:$B$505,$A12,Invoices!$T$6:$T$505,"Issued")+SUMIFS(Invoices!$S$6:$S$505,Invoices!$B$6:$B$505,$A12,Invoices!$T$6:$T$505,"Disputed")) | L12: =IF($A12="","",SUMIFS(Invoices!$S$6:$S$505,Invoices!$B$6:$B$505,$A12,Invoices!$V$6:$V$505,">0"))
J13: =IF($A13="","",COUNTIFS(Invoices!$B$6:$B$505,$A13,Invoices!$T$6:$T$505,"Issued")+COUNTIFS(Invoices!$B$6:$B$505,$A13,Invoices!$T$6:$T$505,"Disputed")) | K13: =IF($A13="","",SUMIFS(Invoices!$S$6:$S$505,Invoices!$B$6:$B$505,$A13,Invoices!$T$6:$T$505,"Issued")+SUMIFS(Invoices!$S$6:$S$505,Invoices!$B$6:$B$505,$A13,Invoices!$T$6:$T$505,"Disputed")) | L13: =IF($A13="","",SUMIFS(Invoices!$S$6:$S$505,Invoices!$B$6:$B$505,$A13,Invoices!$V$6:$V$505,">0"))
J14: =IF($A14="","",COUNTIFS(Invoices!$B$6:$B$505,$A14,Invoices!$T$6:$T$505,"Issued")+COUNTIFS(Invoices!$B$6:$B$505,$A14,Invoices!$T$6:$T$505,"Disputed")) | K14: =IF($A14="","",SUMIFS(Invoices!$S$6:$S$505,Invoices!$B$6:$B$505,$A14,Invoices!$T$6:$T$505,"Issued")+SUMIFS(Invoices!$S$6:$S$505,Invoices!$B$6:$B$505,$A14,Invoices!$T$6:$T$505,"Disputed")) | L14: =IF($A14="","",SUMIFS(Invoices!$S$6:$S$505,Invoices!$B$6:$B$505,$A14,Invoices!$V$6:$V$505,">0"))
J15: =IF($A15="","",COUNTIFS(Invoices!$B$6:$B$505,$A15,Invoices!$T$6:$T$505,"Issued")+COUNTIFS(Invoices!$B$6:$B$505,$A15,Invoices!$T$6:$T$505,"Disputed")) | K15: =IF($A15="","",SUMIFS(Invoices!$S$6:$S$505,Invoices!$B$6:$B$505,$A15,Invoices!$T$6:$T$505,"Issued")+SUMIFS(Invoices!$S$6:$S$505,Invoices!$B$6:$B$505,$A15,Invoices!$T$6:$T$505,"Disputed")) | L15: =IF($A15="","",SUMIFS(Invoices!$S$6:$S$505,Invoices!$B$6:$B$505,$A15,Invoices!$V$6:$V$505,">0"))
J16: =IF($A16="","",COUNTIFS(Invoices!$B$6:$B$505,$A16,Invoices!$T$6:$T$505,"Issued")+COUNTIFS(Invoices!$B$6:$B$505,$A16,Invoices!$T$6:$T$505,"Disputed")) | K16: =IF($A16="","",SUMIFS(Invoices!$S$6:$S$505,Invoices!$B$6:$B$505,$A16,Invoices!$T$6:$T$505,"Issued")+SUMIFS(Invoices!$S$6:$S$505,Invoices!$B$6:$B$505,$A16,Invoices!$T$6:$T$505,"Disputed")) | L16: =IF($A16="","",SUMIFS(Invoices!$S$6:$S$505,Invoices!$B$6:$B$505,$A16,Invoices!$V$6:$V$505,">0"))
J17: =IF($A17="","",COUNTIFS(Invoices!$B$6:$B$505,$A17,Invoices!$T$6:$T$505,"Issued")+COUNTIFS(Invoices!$B$6:$B$505,$A17,Invoices!$T$6:$T$505,"Disputed")) | K17: =IF($A17="","",SUMIFS(Invoices!$S$6:$S$505,Invoices!$B$6:$B$505,$A17,Invoices!$T$6:$T$505,"Issued")+SUMIFS(Invoices!$S$6:$S$505,Invoices!$B$6:$B$505,$A17,Invoices!$T$6:$T$505,"Disputed")) | L17: =IF($A17="","",SUMIFS(Invoices!$S$6:$S$505,Invoices!$B$6:$B$505,$A17,Invoices!$V$6:$V$505,">0"))
J18: =IF($A18="","",COUNTIFS(Invoices!$B$6:$B$505,$A18,Invoices!$T$6:$T$505,"Issued")+COUNTIFS(Invoices!$B$6:$B$505,$A18,Invoices!$T$6:$T$505,"Disputed")) | K18: =IF($A18="","",SUMIFS(Invoices!$S$6:$S$505,Invoices!$B$6:$B$505,$A18,Invoices!$T$6:$T$505,"Issued")+SUMIFS(Invoices!$S$6:$S$505,Invoices!$B$6:$B$505,$A18,Invoices!$T$6:$T$505,"Disputed")) | L18: =IF($A18="","",SUMIFS(Invoices!$S$6:$S$505,Invoices!$B$6:$B$505,$A18,Invoices!$V$6:$V$505,">0"))
... J105: =IF($A105="","",COUNTIFS(Invoices!$B$6:$B$505,$A105,Invoices!$T$6:$T$505,"Issued")+COUNTIFS(Invoices!$B$6:$B$505,$A105,Invoices!$T$6:$T$505,"Disputed")) | K105: =IF($A105="","",SUMIFS(Invoices!$S$6:$S$505,Invoices!$B$6:$B$505,$A105,Invoices!$T$6:$T$505,"Issued")+SUMIFS(Invoices!$S$6:$S$505,Invoices!$B$6:$B$505,$A105,Invoices!$T$6:$T$505,"Disputed")) | L105: =IF($A105="","",SUMIFS(Invoices!$S$6:$S$505,Invoices!$B$6:$B$505,$A105,Invoices!$V$6:$V$505,">0"))

Sheet Lists
A1: Workflow Status | B1: Billing Type | C1: Currency | D1: Payment Method | E1: Credit Note Reason | F1: Credit Note Status | G1: Withholding Certificate | H1: Client Billing Status | I1: Yes / No | K1: Edit the lists to change dropdown options. Keep the first row as the header. Do not rename Workflow Status or Credit Note Status values: formulas depend on Draft, Issued, Disputed and Void.
A2: Draft | B2: Milestone | C2: PHP | D2: Bank transfer | E2: Billing error | F2: Draft | G2: Not applicable | H2: Good standing | I2: Yes
A3: Issued | B3: Time and materials | C3: USD | D3: Online payment | E3: Scope reduction | F3: Approved | G3: Yes | H3: Watch | I3: No
A4: Disputed | B4: Fixed monthly / retainer | C4: EUR | D4: Cheque | E4: Service credit (SLA) | F4: Issued | G4: No, requested | H4: On hold
A5: Void | B5: Deposit / advance | C5: SGD | D5: Cash | E5: Goodwill | F5: Void | H5: Closed
B6: Support plan | C6: AUD | D6: Other | E6: Cancelled service
B7: Expense recharge | C7: GBP
B8: Change request | C8: Other
